Workbook
Name Sections: [2]Filters!$A$2:$A$4

Sheet Corn Processors
A1: num` | B1: CA Co ID | C1: CA Facility ID | D1: EPM prev | E1: EPM | F1: Status | G1: Ownership | H1: Name | I1: State | J1: City | K1: Zip Code | L1: County | M1: PADD | N1: Latitude | O1: Longitude | P1: Year Build | Q1: Technology | R1: Multi-Plant | S1: Efficient Producer | T1: High Pro | U1: CHP | V1: Special Tech | W1: Wind Turbine | X1: White Fox | Y1: Waste heat | Z1: DCO Enhancement | AA1: ICM P10 | AB1: Feedstock | AC1: RINs | AD1: Basis Source | AE1: OPEX | AF1: Air Permit Current | AG1: RIN 2007 | AH1: Report | AI1: State ID | AJ1: Ethanol Capacity | AK1: Ethanol Production | AL1: Corn Grind | AM1: Grain Storage | AN1: Days Storage | AO1: DDGS | AP1: Dryer Types | AQ1: DCO Yield Cat | AR1: DCO Yield (lb/bu) | AS1: DCO Production | AT1: Announced Pipeline | AU1: C02 Pipeline -Direct | AV1: C02 Pipeline -3rd Party | AW1: CI Drop with Pipele | AX1: Sponsor | AY1: CI Drop Potenital | AZ1: CCS Gal (Mln) | BA1: CCS Tons (Mln) | BB1: Corn Acres 2023 | BC1: Public Financials | BD1: Website | BE1: Rail Lines | BF1: Unit Trains (Ethanol) | BG1: Truck ONLY | BH1: Other | BI1: Chinese DDGS Importer | BJ1: RFA Membership | BK1: Index | BL1: Transactions
A2: 1 | B2: 5049 | C2: 70144 | D2: 3546 | E2: 3546 | F2: =IF(A2>0,"Active","Retired") -> Active | G2: Absolute Energy | H2: Absolute Energy | I2: IA | J2: St. Ansgar | K2: 50472 | L2: Mitchell | M2: 2 | N2: 43.49951 | O2: -92.91709 | P2: 2007 | Q2: ICM | R2: =COUNTIF(G:G,"="&G2) -> 1 | S2: EP3 | AB2: Corn | AC2: D6 | AD2: Website | AE2: =IF(BK2=1,"Low","High") -> High | AF2: 150 | AG2: 110 | AH2: 06-A-601 | AJ2: =VLOOKUP(E2,'[1]Ethanol Plant Listing 2025'!$B$3:$E$220,4,FALSE) -> 130 | AK2: =+AJ2*[1]Yield!$K$4 -> 123.5 | AL2: =AK2/VLOOKUP(Q2,[1]Yield!$E$5:$F$14,2,FALSE) -> 41.864407 | AO2: =ROUND((+AL2*13.1*1000000)/2000,-3) -> 274000 | AP2: Rotary Dryer | AQ2: =IF(G2="POET Biorefining",G2,IF(T2="FQPT HI Pro",T2,IF(Z2="ICM FOT",Z2,IF(Q2="ICM",Q2,IF(Q2="ADM",Q2,"None"))))) -> ICM | AR2: =VLOOKUP(AQ2,[1]Yield!$A$5:$B$10,2,FALSE) -> 0.9 | AS2: =(AL2)*AR2 -> 37.677966 | AT2: Likely | AV2: SCS | AX2: =IFERROR(VLOOKUP(E2,[1]Sheet3!$C$2:$E$68,2,FALSE),"None") -> Summit Carbon Solutions | AY2: =IFERROR(VLOOKUP(AX2,[1]Sheet3!$H$3:$I$5,2,FALSE),0) -> 31 | AZ2: =AJ2 -> 130 | BA2: =+AJ2*6.85*0.48/2 -> 213.72 | BB2: =SUMIFS('[1]Corn 2023'!V:V,'[1]Corn 2023'!B:B,"=2023",'[1]Corn 2023'!L:L,"="&'Corn Processors'!L2) -> 151500 | BD2: https://absenergy.org/ | BE2: CP/CN | BF2: Yes | BI2: Importer | BJ2: Member | BK2: =IF(M2=2,10,5)+IF(Q2="ICM",10,5)+IF(X2="Y",10,5) -> 25
A3: 2 | D3: 2856 | E3: 3547 | F3: =IF(A3>0,"Active","Retired") -> Active | G3: ACE Ethanol | H3: =VLOOKUP(E3,'[1]EPA Ethanol Capacity 2024'!$B$5:$C$235,2,FALSE) -> Ace Ethanol LLC | I3: WI | J3: Stanley | K3: 54768 | L3: Chippewa | M3: 2 | N3: 44.9589 | O3: -90.9608 | P3: 2001 | Q3: Delta-T | R3: =COUNTIF(G:G,"="&G3) -> 2 | X3: White Fox ICE | Z3: Fluid Quip | AB3: Corn | AC3: D6/D3 | AD3: Website | AE3: =IF(BK3=1,"Low","High") -> High | AG3: ` | AJ3: =VLOOKUP(E3,'[1]Ethanol Plant Listing 2025'!$B$3:$E$220,4,FALSE) -> 52 | AK3: =+AJ3*[1]Yield!$K$4 -> 49.4 | AL3: =AK3/VLOOKUP(Q3,[1]Yield!$E$5:$F$14,2,FALSE) -> 17.152778 | AO3: =ROUND((+AL3*13.1*1000000)/2000,-3) -> 112000 | AP3: Ring Dryer | AQ3: =IF(G3="POET Biorefining",G3,IF(T3="FQPT HI Pro",T3,IF(Z3="ICM FOT",Z3,IF(Q3="ICM",Q3,IF(Q3="ADM",Q3,"None"))))) -> None | AR3: =VLOOKUP(AQ3,[1]Yield!$A$5:$B$10,2,FALSE) -> 0.815 | AS3: =(AL3)*AR3 -> 13.979514 | AT3: Unlikely | AY3: =IFERROR(VLOOKUP(AX3,[1]Sheet3!$H$3:$I$5,2,FALSE),0) -> 0 | AZ3: =AJ3 -> 52 | BA3: =+AJ3*6.85*0.48/2 -> 85.488 | BB3: =SUMIFS('[1]Corn 2023'!V:V,'[1]Corn 2023'!B:B,"=2023",'[1]Corn 2023'!L:L,"="&'Corn Processors'!L3) -> 0 | BD3: https://www.aceethanol.com/ | BE3: CN | BF3: No | BI3: Importer | BJ3: Member | BK3: =IF(M3=2,10,5)+IF(Q3="ICM",10,5)+IF(X3="Y",10,5) -> 20
A4: 3 | D4: 2857 | E4: 3548 | F4: =IF(A4>0,"Active","Retired") -> Active | G4: Pearl City Elevator | H4: =VLOOKUP(E4,'[1]EPA Ethanol Capacity 2024'!$B$5:$C$235,2,FALSE) -> Adkins Energy LLC | I4: IL | J4: Lena | K4: 61048 | L4: Stephenson | M4: 2 | N4: 42.3586 | O4: -89.80342 | P4: 2002 | Q4: ICM | R4: =COUNTIF(G:G,"="&G4) -> 1 | S4: EP3 | U4: CHP | AB4: Corn | AC4: D6 | AD4: https://pce-coops.com/resources/cashbids/ | AE4: =IF(BK4=1,"Low","High") -> High | AJ4: =VLOOKUP(E4,'[1]Ethanol Plant Listing 2025'!$B$3:$E$220,4,FALSE) -> 60 | AK4: =+AJ4*[1]Yield!$K$4 -> 57 | AL4: =AK4/VLOOKUP(Q4,[1]Yield!$E$5:$F$14,2,FALSE) -> 19.322034 | AO4: =ROUND((+AL4*13.1*1000000)/2000,-3) -> 127000 | AP4: Rotary Dryer | AQ4: =IF(G4="POET Biorefining",G4,IF(T4="FQPT HI Pro",T4,IF(Z4="ICM FOT",Z4,IF(Q4="ICM",Q4,IF(Q4="ADM",Q4,"None"))))) -> ICM | AR4: =VLOOKUP(AQ4,[1]Yield!$A$5:$B$10,2,FALSE) -> 0.9 | AS4: =(AL4)*AR4 -> 17.389831 | AT4: Likely | AY4: =IFERROR(VLOOKUP(AX4,[1]Sheet3!$H$3:$I$5,2,FALSE),0) -> 0 | AZ4: =AJ4 -> 60 | BA4: =+AJ4*6.85*0.48/2 -> 98.64 | BB4: =SUMIFS('[1]Corn 2023'!V:V,'[1]Corn 2023'!B:B,"=2023",'[1]Corn 2023'!L:L,"="&'Corn Processors'!L4) -> 0 | BD4: https://www.adkinsenergy.com/ | BE4: CN | BF4: No | BJ4: Member | BK4: =IF(M4=2,10,5)+IF(Q4="ICM",10,5)+IF(X4="Y",10,5) -> 25
A5: 4 | B5: 3566 | C5: 70234 | D5: 3135 | E5: 3549 | F5: =IF(A5<300,"Active","Retired") -> Active | G5: Aemetis | H5: =VLOOKUP(E5,'[1]EPA Ethanol Capacity 2024'!$B$5:$C$235,2,FALSE) -> Aemetis Advanced Fuels Keys Inc | I5: CA | J5: Keyes | K5: 95307 | L5: Stanislaus | M5: 5 | N5: 37.553007 | O5: -120.91648 | P5: 2006 | Q5: Delta-T | R5: =COUNTIF(G:G,"="&G5) -> 1 | AB5: Corn/Milo | AC5: D6/D5 | AD5: Website | AE5: =IF(BK5=1,"Low","High") -> High | AJ5: =VLOOKUP(E5,'[1]Ethanol Plant Listing 2025'!$B$3:$E$220,4,FALSE) -> 70 | AK5: =+AJ5*[1]Yield!$K$4 -> 66.5 | AL5: =AK5/VLOOKUP(Q5,[1]Yield!$E$5:$F$14,2,FALSE) -> 23.090278 | AO5: =ROUND((+AL5*13.1*1000000)/2000,-3) -> 151000 | AP5: Ring Dryer | AQ5: =IF(G5="POET Biorefining",G5,IF(T5="FQPT HI Pro",T5,IF(Z5="ICM FOT",Z5,IF(Q5="ICM",Q5,IF(Q5="ADM",Q5,"None"))))) -> None | AR5: =VLOOKUP(AQ5,[1]Yield!$A$5:$B$10,2,FALSE) -> 0.815 | AS5: =(AL5)*AR5 -> 18.818576 | AT5: Likely | AY5: =IFERROR(VLOOKUP(AX5,[1]Sheet3!$H$3:$I$5,2,FALSE),0) -> 0 | AZ5: =AJ5 -> 70 | BA5: =+AJ5*6.85*0.48/2 -> 115.08 | BB5: =SUMIFS('[1]Corn 2023'!V:V,'[1]Corn 2023'!B:B,"=2023",'[1]Corn 2023'!L:L,"="&'Corn Processors'!L5) -> 0 | BD5: https://www.aemetis.com/ | BE5: UP | BF5: No | BJ5: Member | BK5: =IF(M5=2,10,5)+IF(Q5="ICM",10,5)+IF(X5="Y",10,5) -> 15
A6: 5 | B6: 4825 | C6: 70087 | D6: 3136 | E6: 3550 | F6: =IF(A6<300,"Active","Retired") -> Active | G6: Al–Corn Clean Fuel | H6: =VLOOKUP(E6,'[1]EPA Ethanol Capacity 2024'!$B$5:$C$235,2,FALSE) -> Al-Corn Clean Fuel | I6: MN | J6: Claremont | K6: 55924 | L6: Dodge | M6: 2 | N6: 44.049412 | O6: -93.017379 | P6: 1996 | Q6: ICM | R6: =COUNTIF(G:G,"="&G6) -> 1 | S6: EP3 | AB6: Corn | AC6: D6 | AD6: Website | AE6: =IF(BK6=1,"Low","High") -> High | AJ6: =VLOOKUP(E6,'[1]Ethanol Plant Listing 2025'!$B$3:$E$220,4,FALSE) -> 130 | AK6: =+AJ6*[1]Yield!$K$4 -> 123.5 | AL6: =AK6/VLOOKUP(Q6,[1]Yield!$E$5:$F$14,2,FALSE) -> 41.864407 | AO6: =ROUND((+AL6*13.1*1000000)/2000,-3) -> 274000 | AP6: Rotary Dryer | AQ6: =IF(G6="POET Biorefining",G6,IF(T6="FQPT HI Pro",T6,IF(Z6="ICM FOT",Z6,IF(Q6="ICM",Q6,IF(Q6="ADM",Q6,"None"))))) -> ICM | AR6: =VLOOKUP(AQ6,[1]Yield!$A$5:$B$10,2,FALSE) -> 0.9 | AS6: =(AL6)*AR6 -> 37.677966 | AT6: Unlikely | AY6: =IFERROR(VLOOKUP(AX6,[1]Sheet3!$H$3:$I$5,2,FALSE),0) -> 0 | AZ6: =AJ6 -> 130 | BA6: =+AJ6*6.85*0.48/2 -> 213.72 | BB6: =SUMIFS('[1]Corn 2023'!V:V,'[1]Corn 2023'!B:B,"=2023",'[1]Corn 2023'!L:L,"="&'Corn Processors'!L6) -> 0 | BD6: http://www.al-corn.com/ | BE6: CP | BF6: Yes | BJ6: Member | BK6: =IF(M6=2,10,5)+IF(Q6="ICM",10,5)+IF(X6="Y",10,5) -> 25
A7: 6 | D7: 3137 | E7: 3551 | F7: =IF(A7<300,"Active","Retired") -> Active | G7: Alto | H7: =VLOOKUP(E7,'[1]EPA Ethanol Capacity 2024'!$B$5:$C$235,2,FALSE) -> Alto Columbia LLC | I7: OR | J7: Boardman | K7: 97818 | L7: Morrow | M7: 5 | N7: 45.855921 | O7: -119.65608 | P7: 2007 | Q7: Delta-T | R7: =COUNTIF(G:G,"="&G7) -> 5 | AB7: Corn | AC7: D6/D5 | AD7: Website | AE7: =IF(BK7=1,"Low","High") -> High | AJ7: =VLOOKUP(E7,'[1]Ethanol Plant Listing 2025'!$B$3:$E$220,4,FALSE) -> 40 | AK7: =+AJ7*[1]Yield!$K$4 -> 38 | AL7: =AK7/VLOOKUP(Q7,[1]Yield!$E$5:$F$14,2,FALSE) -> 13.194444 | AO7: =ROUND((+AL7*13.1*1000000)/2000,-3) -> 86000 | AP7: Ring Dryer | AQ7: =IF(G7="POET Biorefining",G7,IF(T7="FQPT HI Pro",T7,IF(Z7="ICM FOT",Z7,IF(Q7="ICM",Q7,IF(Q7="ADM",Q7,"None"))))) -> None | AR7: =VLOOKUP(AQ7,[1]Yield!$A$5:$B$10,2,FALSE) -> 0.815 | AS7: =(AL7)*AR7 -> 10.753472 | AT7: Likely | AY7: =IFERROR(VLOOKUP(AX7,[1]Sheet3!$H$3:$I$5,2,FALSE),0) -> 0 | AZ7: =AJ7 -> 40 | BA7: =+AJ7*6.85*0.48/2 -> 65.76 | BB7: =SUMIFS('[1]Corn 2023'!V:V,'[1]Corn 2023'!B:B,"=2023",'[1]Corn 2023'!L:L,"="&'Corn Processors'!L7) -> 0 | BC7: Y | BD7: https://www.altoingredients.com/ | BE7: UP | BF7: Yes | BK7: =IF(M7=2,10,5)+IF(Q7="ICM",10,5)+IF(X7="Y",10,5) -> 15
A8: 7 | D8: 3138 | E8: 3552 | F8: =IF(A8<300,"Active","Retired") -> Active | G8: Alto | H8: =VLOOKUP(E8,'[1]EPA Ethanol Capacity 2024'!$B$5:$C$235,2,FALSE) -> Alto Magic Valley Ethanol | I8: ID | J8: Burley | K8: 83318 | L8: Cassia | M8: 4 | N8: 42.521324 | O8: -113.81569 | P8: 2008 | Q8: Delta-T | R8: =COUNTIF(G:G,"="&G8) -> 5 | T8: Harvesting Tech HI PRO | AB8: Corn | AC8: D6 | AD8: Website | AE8: =IF(BK8=1,"Low","High") -> High | AJ8: =VLOOKUP(E8,'[1]Ethanol Plant Listing 2025'!$B$3:$E$220,4,FALSE) -> 60 | AK8: =+AJ8*[1]Yield!$K$4 -> 57 | AL8: =AK8/VLOOKUP(Q8,[1]Yield!$E$5:$F$14,2,FALSE) -> 19.791667 | AO8: =ROUND((+AL8*13.1*1000000)/2000,-3) -> 130000 | AP8: Ring Dryer | AQ8: =IF(G8="POET Biorefining",G8,IF(T8="FQPT HI Pro",T8,IF(Z8="ICM FOT",Z8,IF(Q8="ICM",Q8,IF(Q8="ADM",Q8,"None"))))) -> None | AR8: =VLOOKUP(AQ8,[1]Yield!$A$5:$B$10,2,FALSE) -> 0.815 | AS8: =(AL8)*AR8 -> 16.130208 | AT8: Likely | AY8: =IFERROR(VLOOKUP(AX8,[1]Sheet3!$H$3:$I$5,2,FALSE),0) -> 0 | AZ8: =AJ8 -> 60 | BA8: =+AJ8*6.85*0.48/2 -> 98.64 | BB8: =SUMIFS('[1]Corn 2023'!V:V,'[1]Corn 2023'!B:B,"=2023",'[1]Corn 2023'!L:L,"="&'Corn Processors'!L8) -> 0 | BC8: Y | BD8: https://www.altoingredients.com/ | BE8: UP | BF8: No | BK8: =IF(M8=2,10,5)+IF(Q8="ICM",10,5)+IF(X8="Y",10,5) -> 15
A9: 8 | D9: 3139 | E9: 3553 | F9: =IF(A9<300,"Active","Retired") -> Active | G9: Alto | H9: =VLOOKUP(E9,'[1]EPA Ethanol Capacity 2024'!$B$5:$C$235,2,FALSE) -> Alto ICP LLC | I9: IL | J9: Pekin | K9: 61554 | L9: Tazewell | M9: 2 | N9: 40.555 | O9: -89.6698 | P9: 0 | Q9: Vogelbusch | R9: =COUNTIF(G:G,"="&G9) -> 5 | AB9: Corn | AC9: D6 | AD9: https://www.altoingredients.com/corn-pricing/ | AE9: =IF(BK9=1,"Low","High") -> High | AJ9: =VLOOKUP(E9,'[1]Ethanol Plant Listing 2025'!$B$3:$E$220,4,FALSE) -> 82 | AK9: =+AJ9*[1]Yield!$K$4 -> 77.9 | AL9: =AK9/VLOOKUP(Q9,[1]Yield!$E$5:$F$14,2,FALSE) -> 26.862069 | AO9: =ROUND((+AL9*13.1*1000000)/2000,-3) -> 176000 | AQ9: =IF(G9="POET Biorefining",G9,IF(T9="FQPT HI Pro",T9,IF(Z9="ICM FOT",Z9,IF(Q9="ICM",Q9,IF(Q9="ADM",Q9,"None"))))) -> None | AR9: =VLOOKUP(AQ9,[1]Yield!$A$5:$B$10,2,FALSE) -> 0.815 | AS9: =(AL9)*AR9 -> 21.892586 | AT9: Likely | AY9: =IFERROR(VLOOKUP(AX9,[1]Sheet3!$H$3:$I$5,2,FALSE),0) -> 0 | AZ9: =AJ9 -> 82 | BA9: =+AJ9*6.85*0.48/2 -> 134.808 | BB9: =SUMIFS('[1]Corn 2023'!V:V,'[1]Corn 2023'!B:B,"=2023",'[1]Corn 2023'!L:L,"="&'Corn Processors'!L9) -> 0 | BC9: Y | BD9: https://www.altoingredients.com/ | BE9: IMRR/BNSF | BF9: Yes | BH9: Barge | BK9: =IF(M9=2,10,5)+IF(Q9="ICM",10,5)+IF(X9="Y",10,5) -> 20 | BL9: 6/27/2017 PEIX purchases ICP for $61M
A10: 9 | D10: 3140 | E10: 3554 | F10: =IF(A10<300,"Active","Retired") -> Active | G10: Alto | H10: =VLOOKUP(E10,'[1]EPA Ethanol Capacity 2024'!$B$5:$C$235,2,FALSE) -> Alto Pekin LLC Dry Mill | I10: IL | J10: Pekin | K10: 61554 | L10: Tazewell | M10: 2 | N10: 40.555063 | O10: -89.663302 | P10: 2007 | Q10: ICM | R10: =COUNTIF(G:G,"="&G10) -> 5 | AB10: Corn | AC10: D6 | AD10: https://www.altoingredients.com/corn-pricing/ | AE10: =IF(BK10=1,"Low","High") -> High | AJ10: =VLOOKUP(E10,'[1]Ethanol Plant Listing 2025'!$B$3:$E$220,4,FALSE) -> 63 | AK10: =+AJ10*[1]Yield!$K$4 -> 59.85 | AL10: =AK10/VLOOKUP(Q10,[1]Yield!$E$5:$F$14,2,FALSE) -> 20.288136 | AO10: =ROUND((+AL10*13.1*1000000)/2000,-3) -> 133000 | AP10: Rotary Dryer | AQ10: =IF(G10="POET Biorefining",G10,IF(T10="FQPT HI Pro",T10,IF(Z10="ICM FOT",Z10,IF(Q10="ICM",Q10,IF(Q10="ADM",Q10,"None"))))) -> ICM | AR10: =VLOOKUP(AQ10,[1]Yield!$A$5:$B$10,2,FALSE) -> 0.9 | AS10: =(AL10)*AR10 -> 18.259322 | AT10: Likely | AU10: Direct | AY10: =IFERROR(VLOOKUP(AX10,[1]Sheet3!$H$3:$I$5,2,FALSE),0) -> 0 | AZ10: =AJ10 -> 63 | BA10: =+AJ10*6.85*0.48/2 -> 103.572 | BB10: =SUMIFS('[1]Corn 2023'!V:V,'[1]Corn 2023'!B:B,"=2023",'[1]Corn 2023'!L:L,"="&'Corn Processors'!L10) -> 0 | BC10: Y | BD10: https://www.altoingredients.com/ | BE10: IMRR/BNSF | BF10: Yes | BH10: Barge | BK10: =IF(M10=2,10,5)+IF(Q10="ICM",10,5)+IF(X10="Y",10,5) -> 25 | BL10: 12/2014 PEIX purchases Aventine for $380M (315M gals)
A11: 10 | D11: 3141 | E11: 3555 | F11: =IF(A11<300,"Active","Retired") -> Active | G11: Alto | H11: =VLOOKUP(E11,'[1]EPA Ethanol Capacity 2024'!$B$5:$C$235,2,FALSE) -> Alto Pekin LLC Wet Mill | I11: IL | J11: Pekin | K11: 61554 | L11: Tazewell | M11: 2 | N11: 40.5534 | O11: -89.6631 | P11: 1981 | Q11: Wet Mill | R11: =COUNTIF(G:G,"="&G11) -> 5 | AB11: Corn | AC11: D6 | AD11: https://www.altoingredients.com/corn-pricing/ | AE11: =IF(BK11=1,"Low","High") -> High | AJ11: =VLOOKUP(E11,'[1]Ethanol Plant Listing 2025'!$B$3:$E$220,4,FALSE) -> 100 | AK11: =+AJ11*[1]Yield!$K$4 -> 95 | AL11: =AK11/VLOOKUP(Q11,[1]Yield!$E$5:$F$14,2,FALSE) -> 34.545455 | AO11: =ROUND((+AL11*13.1*1000000)/2000,-3) -> 226000 | AQ11: =IF(G11="POET Biorefining",G11,IF(T11="FQPT HI Pro",T11,IF(Z11="ICM FOT",Z11,IF(Q11="ICM",Q11,IF(Q11="ADM",Q11,"None"))))) -> None | AR11: =VLOOKUP(AQ11,[1]Yield!$A$5:$B$10,2,FALSE) -> 0.815 | AS11: =(AL11)*AR11 -> 28.154545 | AT11: Likely | AU11: Direct | AY11: =IFERROR(VLOOKUP(AX11,[1]Sheet3!$H$3:$I$5,2,FALSE),0) -> 0 | AZ11: =AJ11 -> 100 | BA11: =+AJ11*6.85*0.48/2 -> 164.4 | BB11: =SUMIFS('[1]Corn 2023'!V:V,'[1]Corn 2023'!B:B,"=2023",'[1]Corn 2023'!L:L,"="&'Corn Processors'!L11) -> 0 | BC11: Y | BD11: https://www.altoingredients.com/ | BE11: UP/BNSF/CN/NS/IAIS | BF11: Yes | BH11: Barge | BK11: =IF(M11=2,10,5)+IF(Q11="ICM",10,5)+IF(X11="Y",10,5) -> 20 | BL11: 12/2014 PEIX purchases Aventine for $380M (315M gals)
A12: 11 | E12: 3556 | F12: =IF(A12<300,"Active","Retired") -> Active | G12: Summit Sustainable Ingredients | H12: =VLOOKUP(E12,'[1]EPA Ethanol Capacity 2024'!$B$5:$C$235,2,FALSE) -> Amber Wave | I12: KS | J12: Phillipsburg | K12: 67661 | L12: Phillips | M12: 2 | N12: 38.363339 | O12: -97.783411 | P12: 2023 | Q12: Wheat | R12: =COUNTIF(G:G,"="&G12) -> 1 | AB12: Other Grains | AC12: D6 | AD12: Website | AE12: =IF(BK12=1,"Low","High") -> High | AJ12: =VLOOKUP(E12,'[1]Ethanol Plant Listing 2025'!$B$3:$E$220,4,FALSE) -> 50 | AK12: =+AJ12*[1]Yield!$K$4 -> 47.5 | AL12: =AK12/VLOOKUP(Q12,[1]Yield!$E$5:$F$14,2,FALSE) -> 17.592593 | AO12: =ROUND((+AL12*13.1*1000000)/2000,-3) -> 115000 | AQ12: =IF(G12="POET Biorefining",G12,IF(T12="FQPT HI Pro",T12,IF(Z12="ICM FOT",Z12,IF(Q12="ICM",Q12,IF(Q12="ADM",Q12,IF(Q12="Waste Stream",Q12,IF(Q12="Wheat","Wheat","None"))))))) -> Wheat | AR12: =VLOOKUP(AQ12,[1]Yield!$A$5:$B$15,2,FALSE) -> 0.2 | AS12: =(AL12)*AR12 -> 3.5185185 | AT12: Likely | AY12: =IFERROR(VLOOKUP(AX12,[1]Sheet3!$H$3:$I$5,2,FALSE),0) -> 0 | AZ12: =AJ12 -> 50 | BA12: =+AJ12*6.85*0.48/2 -> 82.2 | BB12: =SUMIFS('[1]Corn 2023'!V:V,'[1]Corn 2023'!B:B,"=2023",'[1]Corn 2023'!L:L,"="&'Corn Processors'!L12) -> 0 | BD12: https://amberwaveusa.com/ | BE12: UP | BF12: No | BK12: =IF(M12=2,10,5)+IF(Q12="ICM",10,5)+IF(X12="Y",10,5) -> 20
A13: 12 | D13: 3142 | E13: 3557 | F13: =IF(A13<300,"Active","Retired") -> Active | G13: ADM | H13: =VLOOKUP(E13,'[1]EPA Ethanol Capacity 2024'!$B$5:$C$235,2,FALSE) -> VCP Corn Processing | I13: IA | J13: Cedar Rapids | K13: 52404 | L13: Linn | M13: 2 | N13: 41.929 | O13: -91.6885 | P13: 2008 | Q13: ADM | R13: =COUNTIF(G:G,"="&G13) -> 8 | U13: CHP | AB13: Corn | AC13: D6 | AD13: Website | AE13: =IF(BK13=1,"Low","High") -> High | AG13: 332.3 | AH13: 04-A-314 | AJ13: =VLOOKUP(E13,'[1]Ethanol Plant Listing 2025'!$B$3:$E$220,4,FALSE) -> 300 | AK13: =+AJ13*[1]Yield!$K$4 -> 285 | AL13: =AK13/VLOOKUP(Q13,[1]Yield!$E$5:$F$14,2,FALSE) -> 98.958333 | AO13: =ROUND((+AL13*13.1*1000000)/2000,-3) -> 648000 | AP13: Rotary Dryer | AQ13: =IF(G13="POET Biorefining",G13,IF(T13="FQPT HI Pro",T13,IF(Z13="ICM FOT",Z13,IF(Q13="ICM",Q13,IF(Q13="ADM",Q13,"None"))))) -> ADM | AR13: =VLOOKUP(AQ13,[1]Yield!$A$5:$B$10,2,FALSE) -> 0.8 | AS13: =(AL13)*AR13 -> 79.166667 | AT13: Y | AY13: =IFERROR(VLOOKUP(AX13,[1]Sheet3!$H$3:$I$5,2,FALSE),0) -> 0 | AZ13: =AJ13 -> 300 | BA13: =+AJ13*6.85*0.48/2 -> 493.2 | BB13: =SUMIFS('[1]Corn 2023'!V:V,'[1]Corn 2023'!B:B,"=2023",'[1]Corn 2023'!L:L,"="&'Corn Processors'!L13) -> 147000 | BC13: Y | BD13: https://www.adm.com/ | BE13: UP | BF13: Yes | BK13: =IF(M13=2,10,5)+IF(Q13="ICM",10,5)+IF(X13="Y",10,5) -> 20
A14: 13 | D14: 3143 | E14: 3558 | F14: =IF(A14<300,"Active","Retired") -> Active | G14: ADM | H14: =VLOOKUP(E14,'[1]EPA Ethanol Capacity 2024'!$B$5:$C$235,2,FALSE) -> ADM Cedar Rapids IA Wet Mill | I14: IA | J14: Cedar Rapids | K14: 52404 | L14: Linn | M14: 2 | N14: 41.9156 | O14: -91.6888 | P14: 0 | Q14: Wet Mill | R14: =COUNTIF(G:G,"="&G14) -> 8 | U14: CHP | AB14: Corn | AC14: D6 | AD14: Website | AE14: =IF(BK14=1,"Low","High") -> High | AF14: 752.325 | AG14: 752.325 | AH14: 07-A-570 | AJ14: =VLOOKUP(E14,'[1]Ethanol Plant Listing 2025'!$B$3:$E$220,4,FALSE) -> 240 | AK14: =+AJ14*[1]Yield!$K$4 -> 228 | AL14: =AK14/VLOOKUP(Q14,[1]Yield!$E$5:$F$14,2,FALSE) -> 82.909091 | AO14: =ROUND((+AL14*13.1*1000000)/2000,-3) -> 543000 | AP14: Rotary Dryer | AQ14: =IF(G14="POET Biorefining",G14,IF(T14="FQPT HI Pro",T14,IF(Z14="ICM FOT",Z14,IF(Q14="ICM",Q14,IF(Q14="ADM",Q14,"None"))))) -> None | AR14: =VLOOKUP(AQ14,[1]Yield!$A$5:$B$10,2,FALSE) -> 0.815 | AS14: =(AL14)*AR14 -> 67.570909 | AT14: Y | AY14: =IFERROR(VLOOKUP(AX14,[1]Sheet3!$H$3:$I$5,2,FALSE),0) -> 0 | AZ14: =AJ14 -> 240 | BA14: =+AJ14*6.85*0.48/2 -> 394.56 | BB14: =SUMIFS('[1]Corn 2023'!V:V,'[1]Corn 2023'!B:B,"=2023",'[1]Corn 2023'!L:L,"="&'Corn Processors'!L14) -> 147000 | BC14: Y | BD14: https://www.adm.com/ | BE14: UP | BF14: Yes | BK14: =IF(M14=2,10,5)+IF(Q14="ICM",10,5)+IF(X14="Y",10,5) -> 20
A15: 14 | D15: 3144 | E15: 3559 | F15: =IF(A15<300,"Active","Retired") -> Active | G15: ADM | H15: =VLOOKUP(E15,'[1]EPA Ethanol Capacity 2024'!$B$5:$C$235,2,FALSE) -> ADM Clinton IA | I15: IA | J15: Clinton | K15: 52732 | L15: Clinton | M15: 2 | N15: 41.8173 | O15: -90.2162 | P15: 2008 | Q15: ADM | R15: =COUNTIF(G:G,"="&G15) -> 8 | U15: CHP | AB15: Corn | AC15: D6 | AD15: Website | AE15: =IF(BK15=1,"Low","High") -> High | AF15: 237.3 | AG15: 237.3 | AH15: 05-A-509 | AJ15: =VLOOKUP(E15,'[1]Ethanol Plant Listing 2025'!$B$3:$E$220,4,FALSE) -> 237 | AK15: =+AJ15*[1]Yield!$K$4 -> 225.15 | AL15: =AK15/VLOOKUP(Q15,[1]Yield!$E$5:$F$14,2,FALSE) -> 78.177083 | AO15: =ROUND((+AL15*13.1*1000000)/2000,-3) -> 512000 | AP15: Rotary Dryer | AQ15: =IF(G15="POET Biorefining",G15,IF(T15="FQPT HI Pro",T15,IF(Z15="ICM FOT",Z15,IF(Q15="ICM",Q15,IF(Q15="ADM",Q15,"None"))))) -> ADM | AR15: =VLOOKUP(AQ15,[1]Yield!$A$5:$B$10,2,FALSE) -> 0.8 | AS15: =(AL15)*AR15 -> 62.541667 | AT15: Y | AY15: =IFERROR(VLOOKUP(AX15,[1]Sheet3!$H$3:$I$5,2,FALSE),0) -> 0 | AZ15: =AJ15 -> 237 | BA15: =+AJ15*6.85*0.48/2 -> 389.628 | BB15: =SUMIFS('[1]Corn 2023'!V:V,'[1]Corn 2023'!B:B,"=2023",'[1]Corn 2023'!L:L,"="&'Corn Processors'!L15) -> 187500 | BC15: Y | BD15: https://www.adm.com/ | BE15: UP/CP | BF15: Yes | BK15: =IF(M15=2,10,5)+IF(Q15="ICM",10,5)+IF(X15="Y",10,5) -> 20
A16: 15 | D16: 3145 | E16: 3560 | F16: =IF(A16<300,"Active","Retired") -> Active | G16: ADM | H16: =VLOOKUP(E16,'[1]EPA Ethanol Capacity 2024'!$B$5:$C$235,2,FALSE) -> VCP Corn Processing | I16: NE | J16: Columbus | K16: 68601 | L16: Platte | M16: 2 | N16: 41.419 | O16: -97.2896 | P16: 2008 | Q16: ADM | R16: =COUNTIF(G:G,"="&G16) -> 8 | U16: CHP | AB16: Corn | AC16: D6 | AD16: Website | AE16: =IF(BK16=1,"Low","High") -> High | AI16: 39285 | AJ16: =VLOOKUP(E16,'[1]Ethanol Plant Listing 2025'!$B$3:$E$220,4,FALSE) -> 313 | AK16: =+AJ16*[1]Yield!$K$4 -> 297.35 | AL16: =AK16/VLOOKUP(Q16,[1]Yield!$E$5:$F$14,2,FALSE) -> 103.24653 | AO16: =ROUND((+AL16*13.1*1000000)/2000,-3) -> 676000 | AP16: Rotary Dryer | AQ16: =IF(G16="POET Biorefining",G16,IF(T16="FQPT HI Pro",T16,IF(Z16="ICM FOT",Z16,IF(Q16="ICM",Q16,IF(Q16="ADM",Q16,"None"))))) -> ADM | AR16: =VLOOKUP(AQ16,[1]Yield!$A$5:$B$10,2,FALSE) -> 0.8 | AS16: =(AL16)*AR16 -> 82.597222 | AT16: Y | AV16: Tall Grass | AX16: =IFERROR(VLOOKUP(E16,[1]Sheet3!$C$2:$E$68,2,FALSE),"None") -> Tall Grass | AY16: =IFERROR(VLOOKUP(AX16,[1]Sheet3!$H$3:$I$5,2,FALSE),0) -> 30 | AZ16: =AJ16 -> 313 | BA16: =+AJ16*6.85*0.48/2 -> 514.572 | BB16: =SUMIFS('[1]Corn 2023'!V:V,'[1]Corn 2023'!B:B,"=2023",'[1]Corn 2023'!L:L,"="&'Corn Processors'!L16) -> 0 | BC16: Y | BD16: https://www.adm.com/ | BE16: UP/BNSF | BF16: Yes | BI16: Impoter | BK16: =IF(M16=2,10,5)+IF(Q16="ICM",10,5)+IF(X16="Y",10,5) -> 20
A17: 16 | D17: 3146 | E17: 3561 | F17: =IF(A17<300,"Active","Retired") -> Active | G17: ADM | H17: =VLOOKUP(E17,'[1]EPA Ethanol Capacity 2024'!$B$5:$C$235,2,FALSE) -> ADM Columbus Wet Mill | I17: NE | J17: Columbus | K17: 68601 | L17: Platte | M17: 2 | N17: 41.4153 | O17: -97.2869 | P17: 1992 | Q17: Wet Mill | R17: =COUNTIF(G:G,"="&G17) -> 8 | U17: CHP | AB17: Corn | AC17: D6 | AD17: Website | AE17: =IF(BK17=1,"Low","High") -> High | AI17: 39285 | AJ17: =VLOOKUP(E17,'[1]Ethanol Plant Listing 2025'!$B$3:$E$220,4,FALSE) -> 100 | AK17: =+AJ17*[1]Yield!$K$4 -> 95 | AL17: =AK17/VLOOKUP(Q17,[1]Yield!$E$5:$F$14,2,FALSE) -> 34.545455 | AO17: =ROUND((+AL17*13.1*1000000)/2000,-3) -> 226000 | AP17: Rotary Dryer | AQ17: =IF(G17="POET Biorefining",G17,IF(T17="FQPT HI Pro",T17,IF(Z17="ICM FOT",Z17,IF(Q17="ICM",Q17,IF(Q17="ADM",Q17,"None"))))) -> None | AR17: =VLOOKUP(AQ17,[1]Yield!$A$5:$B$10,2,FALSE) -> 0.815 | AS17: =(AL17)*AR17 -> 28.154545 | AT17: Y | AV17: Tall Grass | AX17: =IFERROR(VLOOKUP(E17,[1]Sheet3!$C$2:$E$68,2,FALSE),"None") -> Tall Grass | AY17: =IFERROR(VLOOKUP(AX17,[1]Sheet3!$H$3:$I$5,2,FALSE),0) -> 30 | AZ17: =AJ17 -> 100 | BA17: =+AJ17*6.85*0.48/2 -> 164.4 | BB17: =SUMIFS('[1]Corn 2023'!V:V,'[1]Corn 2023'!B:B,"=2023",'[1]Corn 2023'!L:L,"="&'Corn Processors'!L17) -> 0 | BC17: Y | BD17: https://www.adm.com/ | BE17: UP/BNSF | BF17: Yes | BI17: Importer | BK17: =IF(M17=2,10,5)+IF(Q17="ICM",10,5)+IF(X17="Y",10,5) -> 20
A18: 17 | D18: 3147 | E18: 3562 | F18: =IF(A18<300,"Active","Retired") -> Active | G18: ADM | H18: =VLOOKUP(E18,'[1]EPA Ethanol Capacity 2024'!$B$5:$C$235,2,FALSE) -> ADM | I18: IL | J18: Decatur | K18: 62526 | L18: Macon | M18: 2 | N18: 39.8635 | O18: -88.8896 | P18: 0 | Q18: Wet Mill | R18: =COUNTIF(G:G,"="&G18) -> 8 | AB18: Corn | AC18: D6 | AD18: https://adm.gradable.com/market/ | AE18: =IF(BK18=1,"Low","High") -> High | AJ18: =VLOOKUP(E18,'[1]Ethanol Plant Listing 2025'!$B$3:$E$220,4,FALSE) -> 375 | AK18: =+AJ18*[1]Yield!$K$4 -> 356.25 | AL18: =AK18/VLOOKUP(Q18,[1]Yield!$E$5:$F$14,2,FALSE) -> 129.54545 | AO18: =ROUND((+AL18*13.1*1000000)/2000,-3) -> 849000 | AP18: Rotary Dryer | AQ18: =IF(G18="POET Biorefining",G18,IF(T18="FQPT HI Pro",T18,IF(Z18="ICM FOT",Z18,IF(Q18="ICM",Q18,IF(Q18="ADM",Q18,"None"))))) -> None | AR18: =VLOOKUP(AQ18,[1]Yield!$A$5:$B$10,2,FALSE) -> 0.815 | AS18: =(AL18)*AR18 -> 105.57955 | AT18: Y | AU18: Direct | AX18: =IFERROR(VLOOKUP(E18,[1]Sheet3!$C$2:$E$68,2,FALSE),"None") -> Direct Inject | AY18: =IFERROR(VLOOKUP(AX18,[1]Sheet3!$H$3:$I$5,2,FALSE),0) -> 32 | AZ18: =AJ18 -> 375 | BA18: =+AJ18*6.85*0.48/2 -> 616.5 | BB18: =SUMIFS('[1]Corn 2023'!V:V,'[1]Corn 2023'!B:B,"=2023",'[1]Corn 2023'!L:L,"="&'Corn Processors'!L18) -> 0 | BC18: Y | BD18: https://www.adm.com/ | BE18: NS/CN | BF18: Yes | BK18: =IF(M18=2,10,5)+IF(Q18="ICM",10,5)+IF(X18="Y",10,5) -> 20
A19: 18 | D19: 3148 | E19: 3563 | F19: =IF(A19<300,"Active","Retired") -> Active | G19: ADM | H19: =VLOOKUP(E19,'[1]EPA Ethanol Capacity 2024'!$B$5:$C$235,2,FALSE) -> ADM | I19: MN | J19: Marshall | K19: 56258 | L19: Lyon | M19: 2 | N19: 44.4748 | O19: -95.7796 | P19: 1988 | Q19: Wet Mill | R19: =COUNTIF(G:G,"="&G19) -> 8 | AB19: Corn | AC19: D6 | AD19: Website | AE19: =IF(BK19=1,"Low","High") -> High | AJ19: =VLOOKUP(E19,'[1]Ethanol Plant Listing 2025'!$B$3:$E$220,4,FALSE) -> 48 | AK19: =+AJ19*[1]Yield!$K$4 -> 45.6 | AL19: =AK19/VLOOKUP(Q19,[1]Yield!$E$5:$F$14,2,FALSE) -> 16.581818 | AO19: =ROUND((+AL19*13.1*1000000)/2000,-3) -> 109000 | AP19: Rotary Dryer | AQ19: =IF(G19="POET Biorefining",G19,IF(T19="FQPT HI Pro",T19,IF(Z19="ICM FOT",Z19,IF(Q19="ICM",Q19,IF(Q19="ADM",Q19,"None"))))) -> None | AR19: =VLOOKUP(AQ19,[1]Yield!$A$5:$B$10,2,FALSE) -> 0.815 | AS19: =(AL19)*AR19 -> 13.514182 | AT19: Likely | AX19: =IFERROR(VLOOKUP(E19,[1]Sheet3!$C$2:$E$68,2,FALSE),"None") -> None | AY19: =IFERROR(VLOOKUP(AX19,[1]Sheet3!$H$3:$I$5,2,FALSE),0) -> 0 | AZ19: =AJ19 -> 48 | BA19: =+AJ19*6.85*0.48/2 -> 78.912 | BB19: =SUMIFS('[1]Corn 2023'!V:V,'[1]Corn 2023'!B:B,"=2023",'[1]Corn 2023'!L:L,"="&'Corn Processors'!L19) -> 185500 | BC19: Y | BD19: https://www.adm.com/ | BE19: BNSF | BF19: Yes | BK19: =IF(M19=2,10,5)+IF(Q19="ICM",10,5)+IF(X19="Y",10,5) -> 20
A20: 19 | B20: 5715 | C20: 70247 | D20: 3149 | E20: 3564 | F20: =IF(A20<300,"Active","Retired") -> Active | G20: Conestoga Energy | H20: =VLOOKUP(E20,'[1]EPA Ethanol Capacity 2024'!$B$5:$C$235,2,FALSE) -> Arkalon Ethanol LLC | I20: KS | J20: Liberal | K20: 67901 | L20: Seward | M20: 2 | N20: 37.107107 | O20: -101.03083 | P20: 2007 | Q20: ICM | R20: =COUNTIF(G:G,"="&G20) -> 3 | U20: CHP | V20: 3 mw inefficient | AB20: Corn/Milo | AC20: D6 | AD20: Website | AE20: =IF(BK20=1,"Low","High") -> High | AJ20: =VLOOKUP(E20,'[1]Ethanol Plant Listing 2025'!$B$3:$E$220,4,FALSE) -> 121 | AK20: =+AJ20*[1]Yield!$K$4 -> 114.95 | AL20: =AK20/VLOOKUP(Q20,[1]Yield!$E$5:$F$14,2,FALSE) -> 38.966102 | AO20: =ROUND((+AL20*13.1*1000000)/2000,-3) -> 255000 | AP20: Rotary Dryer | AQ20: =IF(G20="POET Biorefining",G20,IF(T20="FQPT HI Pro",T20,IF(Z20="ICM FOT",Z20,IF(Q20="ICM",Q20,IF(Q20="ADM",Q20,"None"))))) -> ICM | AR20: =VLOOKUP(AQ20,[1]Yield!$A$5:$B$10,2,FALSE) -> 0.9 | AS20: =(AL20)*AR20 -> 35.069492 | AT20: Likely | AX20: =IFERROR(VLOOKUP(E20,[1]Sheet3!$C$2:$E$68,2,FALSE),"None") -> None | AY20: =IFERROR(VLOOKUP(AX20,[1]Sheet3!$H$3:$I$5,2,FALSE),0) -> 0 | AZ20: =AJ20 -> 121 | BA20: =+AJ20*6.85*0.48/2 -> 198.924 | BB20: =SUMIFS('[1]Corn 2023'!V:V,'[1]Corn 2023'!B:B,"=2023",'[1]Corn 2023'!L:L,"="&'Corn Processors'!L20) -> 0 | BD20: https://www.conestogaenergy.com/ | BE20: UP | BF20: Yes | BJ20: Member | BK20: =IF(M20=2,10,5)+IF(Q20="ICM",10,5)+IF(X20="Y",10,5) -> 25
A21: 20 | B21: 4469 | C21: 70130 | D21: 2861 | E21: 3567 | F21: =IF(A21<300,"Active","Retired") -> Active | G21: Badger State Ethanol | H21: =VLOOKUP(E21,'[1]EPA Ethanol Capacity 2024'!$B$5:$C$235,2,FALSE) -> Badger State Ethanol LLC | I21: WI | J21: Monroe | K21: 53566 | L21: Green | M21: 2 | N21: 42.5949 | O21: -89.66691 | P21: 2002 | Q21: ICM | R21: =COUNTIF(G:G,"="&G21) -> 1 | S21: EP3 | T21: FQPT HI PRO | Z21: =+T21 -> FQPT HI PRO | AB21: Corn | AC21: D6 | AD21: Website | AE21: =IF(BK21=1,"Low","High") -> High | AJ21: =VLOOKUP(E21,'[1]Ethanol Plant Listing 2025'!$B$3:$E$220,4,FALSE) -> 97 | AK21: =+AJ21*[1]Yield!$K$4 -> 92.15 | AL21: =AK21/VLOOKUP(Q21,[1]Yield!$E$5:$F$14,2,FALSE) -> 31.237288 | AO21: =ROUND((+AL21*13.1*1000000)/2000,-3) -> 205000 | AP21: Rotary Dryer | AQ21: =IF(G21="POET Biorefining",G21,IF(T21="FQPT HI Pro",T21,IF(Z21="ICM FOT",Z21,IF(Q21="ICM",Q21,IF(Q21="ADM",Q21,"None"))))) -> FQPT HI PRO | AR21: =VLOOKUP(AQ21,[1]Yield!$A$5:$B$10,2,FALSE) -> 1.05 | AS21: =(AL21)*AR21 -> 32.799153 | AT21: Likely | AX21: =IFERROR(VLOOKUP(E21,[1]Sheet3!$C$2:$E$68,2,FALSE),"None") -> None | AY21: =IFERROR(VLOOKUP(AX21,[1]Sheet3!$H$3:$I$5,2,FALSE),0) -> 0 | AZ21: =AJ21 -> 97 | BA21: =+AJ21*6.85*0.48/2 -> 159.468 | BB21: =SUMIFS('[1]Corn 2023'!V:V,'[1]Corn 2023'!B:B,"=2023",'[1]Corn 2023'!L:L,"="&'Corn Processors'!L21) -> 0 | BD21: https://badgerstateethanol.com/ | BE21: UP | BF21: Yes | BI21: Importer | BJ21: Member | BK21: =IF(M21=2,10,5)+IF(Q21="ICM",10,5)+IF(X21="Y",10,5) -> 25
A22: 21 | D22: 2862 | E22: 3568 | F22: =IF(A22<300,"Active","Retired") -> Active | G22: Big River Resources | H22: =VLOOKUP(E22,'[1]EPA Ethanol Capacity 2024'!$B$5:$C$235,2,FALSE) -> Big River Resources Boyceville LLC | I22: WI | J22: Boyceville | K22: 54725 | L22: Dunn | M22: 2 | N22: 45.050596 | O22: -91.980063 | P22: 2006 | Q22: ICM | R22: =COUNTIF(G:G,"="&G22) -> 4 | AB22: Corn | AC22: D6 | AD22: Website | AE22: =IF(BK22=1,"Low","High") -> High | AJ22: =VLOOKUP(E22,'[1]Ethanol Plant Listing 2025'!$B$3:$E$220,4,FALSE) -> 70 | AK22: =+AJ22*[1]Yield!$K$4 -> 66.5 | AL22: =AK22/VLOOKUP(Q22,[1]Yield!$E$5:$F$14,2,FALSE) -> 22.542373 | AO22: =ROUND((+AL22*13.1*1000000)/2000,-3) -> 148000 | AP22: Rotary Dryer | AQ22: =IF(G22="POET Biorefining",G22,IF(T22="FQPT HI Pro",T22,IF(Z22="ICM FOT",Z22,IF(Q22="ICM",Q22,IF(Q22="ADM",Q22,"None"))))) -> ICM | AR22: =VLOOKUP(AQ22,[1]Yield!$A$5:$B$10,2,FALSE) -> 0.9 | AS22: =(AL22)*AR22 -> 20.288136 | AT22: Unlikely | AX22: =IFERROR(VLOOKUP(E22,[1]Sheet3!$C$2:$E$68,2,FALSE),"None") -> None | AY22: =IFERROR(VLOOKUP(AX22,[1]Sheet3!$H$3:$I$5,2,FALSE),0) -> 0 | AZ22: =AJ22 -> 70 | BA22: =+AJ22*6.85*0.48/2 -> 115.08 | BB22: =SUMIFS('[1]Corn 2023'!V:V,'[1]Corn 2023'!K:K,"="&'Corn Processors'!J22,'[1]Corn 2023'!B:B,"=2023") -> 0 | BD22: https://www.bigriverresources.com/ | BE22: CN | BF22: Yes | BI22: Importer | BJ22: Member | BK22: =IF(M22=2,10,5)+IF(Q22="ICM",10,5)+IF(X22="Y",10,5) -> 25
A23: 22 | D23: 2863 | E23: 3569 | F23: =IF(A23<300,"Active","Retired") -> Active | G23: Big River Resources | H23: =VLOOKUP(E23,'[1]EPA Ethanol Capacity 2024'!$B$5:$C$235,2,FALSE) -> Big River Resources Galva LLC | I23: IL | J23: Galva | K23: 61434 | L23: Henry | M23: 2 | N23: 41.169691 | O23: -90.024473 | P23: 2009 | Q23: ICM | R23: =COUNTIF(G:G,"="&G23) -> 4 | S23: EP3 | AB23: Corn | AC23: D6 | AD23: https://www.rivervalleycoop.com/products-services/grain#grain-bids | AE23: =IF(BK23=1,"Low","High") -> High | AJ23: =VLOOKUP(E23,'[1]Ethanol Plant Listing 2025'!$B$3:$E$220,4,FALSE) -> 140 | AK23: =+AJ23*[1]Yield!$K$4 -> 133 | AL23: =AK23/VLOOKUP(Q23,[1]Yield!$E$5:$F$14,2,FALSE) -> 45.084746 | AO23: =ROUND((+AL23*13.1*1000000)/2000,-3) -> 295000 | AP23: Rotary Dryer | AQ23: =IF(G23="POET Biorefining",G23,IF(T23="FQPT HI Pro",T23,IF(Z23="ICM FOT",Z23,IF(Q23="ICM",Q23,IF(Q23="ADM",Q23,"None"))))) -> ICM | AR23: =VLOOKUP(AQ23,[1]Yield!$A$5:$B$10,2,FALSE) -> 0.9 | AS23: =(AL23)*AR23 -> 40.576271 | AT23: Y | AU23: Direct | AX23: Direct Inject | AY23: =IFERROR(VLOOKUP(AX23,[1]Sheet3!$H$3:$I$5,2,FALSE),0) -> 32 | AZ23: =AJ23 -> 140 | BA23: =+AJ23*6.85*0.48/2 -> 230.16 | BB23: =SUMIFS('[1]Corn 2023'!V:V,'[1]Corn 2023'!K:K,"="&'Corn Processors'!J23,'[1]Corn 2023'!B:B,"=2023") -> 0 | BD23: https://www.bigriverresources.com/ | BE23: BNSF | BF23: Yes | BJ23: Member | BK23: =IF(M23=2,10,5)+IF(Q23="ICM",10,5)+IF(X23="Y",10,5) -> 25
A24: 23 | D24: 2864 | E24: 3570 | F24: =IF(A24<300,"Active","Retired") -> Active | G24: Big River Resources | H24: =VLOOKUP(E24,'[1]EPA Ethanol Capacity 2024'!$B$5:$C$235,2,FALSE) -> Big River Resources West Burlington LLC | I24: IA | J24: West Burlington | K24: 52655 | L24: Des Moines | M24: 2 | N24: 40.831196 | O24: -91.220611 | P24: 2008 | Q24: ICM | R24: =COUNTIF(G:G,"="&G24) -> 4 | AB24: Corn | AC24: D6 | AD24: Website | AE24: =IF(BK24=1,"Low","High") -> High | AF24: 130 | AG24: 130 | AH24: 06-A-631 | AJ24: =VLOOKUP(E24,'[1]Ethanol Plant Listing 2025'!$B$3:$E$220,4,FALSE) -> 130 | AK24: =+AJ24*[1]Yield!$K$4 -> 123.5 | AL24: =AK24/VLOOKUP(Q24,[1]Yield!$E$5:$F$14,2,FALSE) -> 41.864407 | AO24: =ROUND((+AL24*13.1*1000000)/2000,-3) -> 274000 | AP24: Rotary Dryer | AQ24: =IF(G24="POET Biorefining",G24,IF(T24="FQPT HI Pro",T24,IF(Z24="ICM FOT",Z24,IF(Q24="ICM",Q24,IF(Q24="ADM",Q24,"None"))))) -> ICM | AR24: =VLOOKUP(AQ24,[1]Yield!$A$5:$B$10,2,FALSE) -> 0.9 | AS24: =(AL24)*AR24 -> 37.677966 | AT24: Y | AX24: =IFERROR(VLOOKUP(E24,[1]Sheet3!$C$2:$E$68,2,FALSE),"None") -> None | AY24: =IFERROR(VLOOKUP(AX24,[1]Sheet3!$H$3:$I$5,2,FALSE),0) -> 0 | AZ24: =AJ24 -> 130 | BA24: =+AJ24*6.85*0.48/2 -> 213.72 | BB24: =SUMIFS('[1]Corn 2023'!V:V,'[1]Corn 2023'!B:B,"=2023",'[1]Corn 2023'!L:L,"="&'Corn Processors'!L24) -> 74200 | BD24: https://www.bigriverresources.com/ | BE24: BNSF | BF24: Yes | BI24: Importer | BJ24: Member | BK24: =IF(M24=2,10,5)+IF(Q24="ICM",10,5)+IF(X24="Y",10,5) -> 25
A25: 24 | D25: 3153 | E25: 3571 | F25: =IF(A25<300,"Active","Retired") -> Active | G25: Big River Resources | H25: =VLOOKUP(E25,'[1]EPA Ethanol Capacity 2024'!$B$5:$C$235,2,FALSE) -> Big River United Energy LLC | I25: IA | J25: Dyersville | K25: 52040 | L25: Dubuque | M25: 2 | N25: 42.4872 | O25: -91.1633 | P25: 2009 | Q25: ICM | R25: =COUNTIF(G:G,"="&G25) -> 4 | S25: EP3 | AB25: Corn | AC25: D6 | AD25: Website | AE25: =IF(BK25=1,"Low","High") -> High | AF25: 140 | AG25: 120 | AH25: 06-A-725 | AJ25: =VLOOKUP(E25,'[1]Ethanol Plant Listing 2025'!$B$3:$E$220,4,FALSE) -> 140 | AK25: =+AJ25*[1]Yield!$K$4 -> 133 | AL25: =AK25/VLOOKUP(Q25,[1]Yield!$E$5:$F$14,2,FALSE) -> 45.084746 | AO25: =ROUND((+AL25*13.1*1000000)/2000,-3) -> 295000 | AP25: Rotary Dryer | AQ25: =IF(G25="POET Biorefining",G25,IF(T25="FQPT HI Pro",T25,IF(Z25="ICM FOT",Z25,IF(Q25="ICM",Q25,IF(Q25="ADM",Q25,"None"))))) -> ICM | AR25: =VLOOKUP(AQ25,[1]Yield!$A$5:$B$10,2,FALSE) -> 0.9 | AS25: =(AL25)*AR25 -> 40.576271 | AT25: Y | AX25: =IFERROR(VLOOKUP(E25,[1]Sheet3!$C$2:$E$68,2,FALSE),"None") -> None | AY25: =IFERROR(VLOOKUP(AX25,[1]Sheet3!$H$3:$I$5,2,FALSE),0) -> 0 | AZ25: =AJ25 -> 140 | BA25: =+AJ25*6.85*0.48/2 -> 230.16 | BB25: =SUMIFS('[1]Corn 2023'!V:V,'[1]Corn 2023'!B:B,"=2023",'[1]Corn 2023'!L:L,"="&'Corn Processors'!L25) -> 148500 | BD25: https://www.bigriverresources.com/ | BE25: CN | BF25: Yes | BI25: Importer | BJ25: Member | BK25: =IF(M25=2,10,5)+IF(Q25="ICM",10,5)+IF(X25="Y",10,5) -> 25 | BL25: 3/17/09 AgStar Financial purcahses US BioEnergy assets out of bancruptcy for $??M
A26: 25 | D26: 3154 | E26: 3572 | F26: =IF(A26<300,"Active","Retired") -> Active | G26: BioUrja | H26: =VLOOKUP(E26,'[1]EPA Ethanol Capacity 2024'!$B$5:$C$235,2,FALSE) -> Biourja Renewables LLC | I26: IL | J26: Peoria | K26: 61602 | L26: Peoria | M26: 2 | N26: 40.6776 | O26: -89.6069 | P26: 1982 | Q26: ADM | R26: =COUNTIF(G:G,"="&G26) -> 1 | AB26: Corn | AC26: D6 | AD26: https://www.rivervalleycoop.com/products-services/grain#grain-bids | AE26: =IF(BK26=1,"Low","High") -> High | AJ26: =VLOOKUP(E26,'[1]Ethanol Plant Listing 2025'!$B$3:$E$220,4,FALSE) -> 61 | AK26: =+AJ26*[1]Yield!$K$4 -> 57.95 | AL26: =AK26/VLOOKUP(Q26,[1]Yield!$E$5:$F$14,2,FALSE) -> 20.121528 | AO26: =ROUND((+AL26*13.1*1000000)/2000,-3) -> 132000 | AP26: Rotary Dryer | AQ26: =IF(G26="POET Biorefining",G26,IF(T26="FQPT HI Pro",T26,IF(Z26="ICM FOT",Z26,IF(Q26="ICM",Q26,IF(Q26="ADM",Q26,"None"))))) -> ADM | AR26: =VLOOKUP(AQ26,[1]Yield!$A$5:$B$10,2,FALSE) -> 0.8 | AS26: =(AL26)*AR26 -> 16.097222 | AT26: Likely | AX26: =IFERROR(VLOOKUP(E26,[1]Sheet3!$C$2:$E$68,2,FALSE),"None") -> None | AY26: =IFERROR(VLOOKUP(AX26,[1]Sheet3!$H$3:$I$5,2,FALSE),0) -> 0 | AZ26: =AJ26 -> 61 | BA26: =+AJ26*6.85*0.48/2 -> 100.284 | BB26: =SUMIFS('[1]Corn 2023'!V:V,'[1]Corn 2023'!K:K,"="&'Corn Processors'!J26,'[1]Corn 2023'!B:B,"=2023") -> 0 | BD26: https://www.biourja.com/ | BE26: UP | BF26: Yes | BK26: =IF(M26=2,10,5)+IF(Q26="ICM",10,5)+IF(X26="Y",10,5) -> 20 | BL26: 10/21/21 BioUrja purcahses from ADM
A27: 26 | D27: 3155 | E27: 3573 | F27: =IF(A27<300,"Active","Retired") -> Active | G27: Harvestone | H27: =VLOOKUP(E27,'[1]EPA Ethanol Capacity 2024'!$B$5:$C$235,2,FALSE) -> Blue Flint Ethanol LLC | I27: ND | J27: Underwood | K27: 58576 | L27: McLean | M27: 2 | N27: 47.377226 | O27: -101.1523 | P27: 2007 | Q27: ICM | R27: =COUNTIF(G:G,"="&G27) -> 3 | U27: CHP | AB27: Corn | AC27: D6 | AD27: Website | AE27: =IF(BK27=1,"Low","High") -> High | AJ27: =VLOOKUP(E27,'[1]Ethanol Plant Listing 2025'!$B$3:$E$220,4,FALSE) -> 75.7 | AK27: =+AJ27*[1]Yield!$K$4 -> 71.915 | AL27: =AK27/VLOOKUP(Q27,[1]Yield!$E$5:$F$14,2,FALSE) -> 24.377966 | AO27: =ROUND((+AL27*13.1*1000000)/2000,-3) -> 160000 | AP27: Rotary Dryer | AQ27: =IF(G27="POET Biorefining",G27,IF(T27="FQPT HI Pro",T27,IF(Z27="ICM FOT",Z27,IF(Q27="ICM",Q27,IF(Q27="ADM",Q27,"None"))))) -> ICM | AR27: =VLOOKUP(AQ27,[1]Yield!$A$5:$B$10,2,FALSE) -> 0.9 | AS27: =(AL27)*AR27 -> 21.940169 | AT27: Likely | AU27: Direct | AX27: =IFERROR(VLOOKUP(E27,[1]Sheet3!$C$2:$E$68,2,FALSE),"None") -> Direct Inject | AY27: =IFERROR(VLOOKUP(AX27,[1]Sheet3!$H$3:$I$5,2,FALSE),0) -> 32 | AZ27: =AJ27 -> 75.7 | BA27: =+AJ27*6.85*0.48/2 -> 124.4508 | BB27: =SUMIFS('[1]Corn 2023'!V:V,'[1]Corn 2023'!K:K,"="&'Corn Processors'!J27,'[1]Corn 2023'!B:B,"=2023") -> 0 | BD27: https://www.midwestagenergy.com/fccp-blue-flint-19634 | BE27: UP | BF27: Yes | BK27: =IF(M27=2,10,5)+IF(Q27="ICM",10,5)+IF(X27="Y",10,5) -> 25
A28: 27 | B28: 4054 | C28: 70117 | D28: 3156 | E28: 3574 | F28: =IF(A28<300,"Active","Retired") -> Active | G28: Conestoga Energy | H28: =VLOOKUP(E28,'[1]EPA Ethanol Capacity 2024'!$B$5:$C$235,2,FALSE) -> Bonanza Bioenergy LLC | I28: KS | J28: Garden City | K28: 33923 | L28: #N/A | M28: 2 | N28: 37.959051 | O28: -100.83913 | P28: 2007 | Q28: ICM | R28: =COUNTIF(G:G,"="&G28) -> 3 | U28: CHP | AB28: Corn/Milo | AC28: D6 | AD28: Website | AE28: =IF(BK28=1,"Low","High") -> High | AJ28: =VLOOKUP(E28,'[1]Ethanol Plant Listing 2025'!$B$3:$E$220,4,FALSE) -> 73.5 | AK28: =+AJ28*[1]Yield!$K$4 -> 69.825 | AL28: =AK28/VLOOKUP(Q28,[1]Yield!$E$5:$F$14,2,FALSE) -> 23.669492 | AO28: =ROUND((+AL28*13.1*1000000)/2000,-3) -> 155000 | AP28: Rotary Dryer | AQ28: =IF(G28="POET Biorefining",G28,IF(T28="FQPT HI Pro",T28,IF(Z28="ICM FOT",Z28,IF(Q28="ICM",Q28,IF(Q28="ADM",Q28,"None"))))) -> ICM | AR28: =VLOOKUP(AQ28,[1]Yield!$A$5:$B$10,2,FALSE) -> 0.9 | AS28: =(AL28)*AR28 -> 21.302542 | AT28: Likely | AU28: Direct | AX28: =IFERROR(VLOOKUP(E28,[1]Sheet3!$C$2:$E$68,2,FALSE),"None") -> Direct Inject | AY28: =IFERROR(VLOOKUP(AX28,[1]Sheet3!$H$3:$I$5,2,FALSE),0) -> 32 | AZ28: =AJ28 -> 73.5 | BA28: =+AJ28*6.85*0.48/2 -> 120.834 | BB28: =SUMIFS('[1]Corn 2023'!V:V,'[1]Corn 2023'!K:K,"="&'Corn Processors'!J28,'[1]Corn 2023'!B:B,"=2023") -> 0 | BD28: https://www.conestogaenergy.com/ | BE28: BNSF | BF28: Yes | BK28: =IF(M28=2,10,5)+IF(Q28="ICM",10,5)+IF(X28="Y",10,5) -> 25
A29: 28 | B29: 5934 | C29: 70217 | D29: 3157 | E29: 3575 | F29: =IF(A29<300,"Active","Retired") -> Active | G29: Bridgeport Ethanol | H29: =VLOOKUP(E29,'[1]EPA Ethanol Capacity 2024'!$B$5:$C$235,2,FALSE) -> Bridgeport Ethanol LLC | I29: NE | J29: Bridgeport | K29: 69336 | L29: Morrill | M29: 2 | N29: 41.6432 | O29: -103.07863 | P29: 2008 | Q29: ICM | R29: =COUNTIF(G:G,"="&G29) -> 1 | U29: CHP | AB29: Corn | AC29: D6 | AD29: Website | AE29: =IF(BK29=1,"Low","High") -> High | AF29: 60 | AG29: 50 | AH29: AIR>CONSTRUCTION | AI29: 87464 | AJ29: =VLOOKUP(E29,'[1]Ethanol Plant Listing 2025'!$B$3:$E$220,4,FALSE) -> 60 | AK29: =+AJ29*[1]Yield!$K$4 -> 57 | AL29: =AK29/VLOOKUP(Q29,[1]Yield!$E$5:$F$14,2,FALSE) -> 19.322034 | AO29: =ROUND((+AL29*13.1*1000000)/2000,-3) -> 127000 | AP29: Rotary Dryer | AQ29: =IF(G29="POET Biorefining",G29,IF(T29="FQPT HI Pro",T29,IF(Z29="ICM FOT",Z29,IF(Q29="ICM",Q29,IF(Q29="ADM",Q29,"None"))))) -> ICM | AR29: =VLOOKUP(AQ29,[1]Yield!$A$5:$B$10,2,FALSE) -> 0.9 | AS29: =(AL29)*AR29 -> 17.389831 | AT29: Y | AX29: =IFERROR(VLOOKUP(E29,[1]Sheet3!$C$2:$E$68,2,FALSE),"None") -> None | AY29: =IFERROR(VLOOKUP(AX29,[1]Sheet3!$H$3:$I$5,2,FALSE),0) -> 0 | AZ29: =AJ29 -> 60 | BA29: =+AJ29*6.85*0.48/2 -> 98.64 | BB29: =SUMIFS('[1]Corn 2023'!V:V,'[1]Corn 2023'!K:K,"="&'Corn Processors'!J29,'[1]Corn 2023'!B:B,"=2023") -> 0 | BD29: http://www.bridgeportethanol.com/index.cfm?show=10&mid=29 | BE29: BNSF | BF29: Yes | BK29: =IF(M29=2,10,5)+IF(Q29="ICM",10,5)+IF(X29="Y",10,5) -> 25
A30: 29 | B30: 4063 | C30: 70109 | D30: 3158 | E30: 3576 | F30: =IF(A30<300,"Active","Retired") -> Active | G30: Bushmills Ethanol Inc. | H30: =VLOOKUP(E30,'[1]EPA Ethanol Capacity 2024'!$B$5:$C$235,2,FALSE) -> Bushmills Ethanol Inc | I30: MN | J30: Atwater | K30: 56209 | L30: Kandiyohi | M30: 2 | N30: 45.07333 | O30: -94.755556 | P30: 2005 | Q30: ICM | R30: =COUNTIF(G:G,"="&G30) -> 1 | S30: EP3 | AB30: Corn | AC30: D6 | AD30: Website | AE30: =IF(BK30=1,"Low","High") -> High | AJ30: =VLOOKUP(E30,'[1]Ethanol Plant Listing 2025'!$B$3:$E$220,4,FALSE) -> 90 | AK30: =+AJ30*[1]Yield!$K$4 -> 85.5 | AL30: =AK30/VLOOKUP(Q30,[1]Yield!$E$5:$F$14,2,FALSE) -> 28.983051 | AO30: =ROUND((+AL30*13.1*1000000)/2000,-3) -> 190000 | AP30: Rotary Dryer | AQ30: =IF(G30="POET Biorefining",G30,IF(T30="FQPT HI Pro",T30,IF(Z30="ICM FOT",Z30,IF(Q30="ICM",Q30,IF(Q30="ADM",Q30,"None"))))) -> ICM | AR30: =VLOOKUP(AQ30,[1]Yield!$A$5:$B$10,2,FALSE) -> 0.9 | AS30: =(AL30)*AR30 -> 26.084746 | AT30: Y | AX30: =IFERROR(VLOOKUP(E30,[1]Sheet3!$C$2:$E$68,2,FALSE),"None") -> Summit Carbon Solutions | AY30: =IFERROR(VLOOKUP(AX30,[1]Sheet3!$H$3:$I$5,2,FALSE),0) -> 31 | AZ30: =AJ30 -> 90 | BA30: =+AJ30*6.85*0.48/2 -> 147.96 | BB30: =SUMIFS('[1]Corn 2023'!V:V,'[1]Corn 2023'!K:K,"="&'Corn Processors'!J30,'[1]Corn 2023'!B:B,"=2023") -> 0 | BD30: https://bushmillsethanol.com/ | BE30: BNSF | BF30: Yes | BK30: =IF(M30=2,10,5)+IF(Q30="ICM",10,5)+IF(X30="Y",10,5) -> 25
A31: 30 | B31: 7354 | C31: 70317 | D31: 3159 | E31: 3577 | F31: =IF(A31<300,"Active","Retired") -> Active | G31: Calgren Renewable Fuels | H31: =VLOOKUP(E31,'[1]EPA Ethanol Capacity 2024'!$B$5:$C$235,2,FALSE) -> Calgren Renewable Fuels LLC | I31: CA | J31: Pixley | K31: 93256 | L31: Tulare | M31: 5 | N31: 36.0019 | O31: -119.30233 | P31: 2009 | Q31: Lurgi | R31: =COUNTIF(G:G,"="&G31) -> 1 | U31: CHP | AB31: Corn | AC31: D6 | AD31: Website | AE31: =IF(BK31=1,"Low","High") -> High | AJ31: =VLOOKUP(E31,'[1]Ethanol Plant Listing 2025'!$B$3:$E$220,4,FALSE) -> 55 | AK31: =+AJ31*[1]Yield!$K$4 -> 52.25 | AL31: =AK31/VLOOKUP(Q31,[1]Yield!$E$5:$F$14,2,FALSE) -> 18.333333 | AO31: =ROUND((+AL31*13.1*1000000)/2000,-3) -> 120000 | AQ31: =IF(G31="POET Biorefining",G31,IF(T31="FQPT HI Pro",T31,IF(Z31="ICM FOT",Z31,IF(Q31="ICM",Q31,IF(Q31="ADM",Q31,"None"))))) -> None | AR31: =VLOOKUP(AQ31,[1]Yield!$A$5:$B$10,2,FALSE) -> 0.815 | AS31: =(AL31)*AR31 -> 14.941667 | AT31: Likely | AX31: =IFERROR(VLOOKUP(E31,[1]Sheet3!$C$2:$E$68,2,FALSE),"None") -> None | AY31: =IFERROR(VLOOKUP(AX31,[1]Sheet3!$H$3:$I$5,2,FALSE),0) -> 0 | AZ31: =AJ31 -> 55 | BA31: =+AJ31*6.85*0.48/2 -> 90.42 | BB31: =SUMIFS('[1]Corn 2023'!V:V,'[1]Corn 2023'!K:K,"="&'Corn Processors'!J31,'[1]Corn 2023'!B:B,"=2023") -> 0 | BD31: https://www.calgren.com/ | BE31: UP | BF31: No | BJ31: Member | BK31: =IF(M31=2,10,5)+IF(Q31="ICM",10,5)+IF(X31="Y",10,5) -> 15
A32: 31 | D32: 3160 | E32: 3578 | F32: =IF(A32<300,"Active","Retired") -> Active | G32: Carbon Green Bioenergy | H32: =VLOOKUP(E32,'[1]EPA Ethanol Capacity 2024'!$B$5:$C$235,2,FALSE) -> Carbon Green Bioenergy LLC | I32: MI | J32: Lake Odessa | K32: 48849 | L32: Ionia | M32: 2 | N32: 42.76601 | O32: -85.07428 | P32: 2006 | Q32: ICM | R32: =COUNTIF(G:G,"="&G32) -> 1 | S32: EP3 | AB32: Corn | AC32: D6 | AD32: Website | AE32: =IF(BK32=1,"Low","High") -> High | AJ32: =VLOOKUP(E32,'[1]Ethanol Plant Listing 2025'!$B$3:$E$220,4,FALSE) -> 59 | AK32: =+AJ32*[1]Yield!$K$4 -> 56.05 | AL32: =AK32/VLOOKUP(Q32,[1]Yield!$E$5:$F$14,2,FALSE) -> 19 | AO32: =ROUND((+AL32*13.1*1000000)/2000,-3) -> 124000 | AP32: Rotary Dryer | AQ32: =IF(G32="POET Biorefining",G32,IF(T32="FQPT HI Pro",T32,IF(Z32="ICM FOT",Z32,IF(Q32="ICM",Q32,IF(Q32="ADM",Q32,"None"))))) -> ICM | AR32: =VLOOKUP(AQ32,[1]Yield!$A$5:$B$10,2,FALSE) -> 0.9 | AS32: =(AL32)*AR32 -> 17.1 | AT32: Likely | AX32: =IFERROR(VLOOKUP(E32,[1]Sheet3!$C$2:$E$68,2,FALSE),"None") -> None | AY32: =IFERROR(VLOOKUP(AX32,[1]Sheet3!$H$3:$I$5,2,FALSE),0) -> 0 | AZ32: =AJ32 -> 59 | BA32: =+AJ32*6.85*0.48/2 -> 96.996 | BB32: =SUMIFS('[1]Corn 2023'!V:V,'[1]Corn 2023'!K:K,"="&'Corn Processors'!J32,'[1]Corn 2023'!B:B,"=2023") -> 0 | BD32: https://cgbioenergy.com/ | BE32: CSX | BF32: No | BK32: =IF(M32=2,10,5)+IF(Q32="ICM",10,5)+IF(X32="Y",10,5) -> 25
A33: 32 | D33: 3161 | E33: 3579 | F33: =IF(A33<300,"Active","Retired") -> Active | G33: Cardinal Ethanol | H33: =VLOOKUP(E33,'[1]EPA Ethanol Capacity 2024'!$B$5:$C$235,2,FALSE) -> Cardinal Ethanol LLC | I33: IN | J33: Union City | K33: 47390 | L33: Randolph | M33: 2 | N33: 40.18682 | O33: -84.86226 | P33: 2008 | Q33: ICM | R33: =COUNTIF(G:G,"="&G33) -> 2 | S33: EP3 | T33: ICM HI PRO | AB33: Corn | AC33: D6 | AD33: Website | AE33: =IF(BK33=1,"Low","High") -> High | AJ33: =VLOOKUP(E33,'[1]Ethanol Plant Listing 2025'!$B$3:$E$220,4,FALSE) -> 136 | AK33: =+AJ33*[1]Yield!$K$4 -> 129.2 | AL33: =AK33/VLOOKUP(Q33,[1]Yield!$E$5:$F$14,2,FALSE) -> 43.79661 | AO33: =ROUND((+AL33*13.1*1000000)/2000,-3) -> 287000 | AP33: Rotary Dryer | AQ33: =IF(G33="POET Biorefining",G33,IF(T33="FQPT HI Pro",T33,IF(Z33="ICM FOT",Z33,IF(Q33="ICM",Q33,IF(Q33="ADM",Q33,"None"))))) -> ICM | AR33: =VLOOKUP(AQ33,[1]Yield!$A$5:$B$10,2,FALSE) -> 0.9 | AS33: =(AL33)*AR33 -> 39.416949 | AT33: Likely | AX33: =IFERROR(VLOOKUP(E33,[1]Sheet3!$C$2:$E$68,2,FALSE),"None") -> None | AY33: =IFERROR(VLOOKUP(AX33,[1]Sheet3!$H$3:$I$5,2,FALSE),0) -> 0 | AZ33: =AJ33 -> 136 | BA33: =+AJ33*6.85*0.48/2 -> 223.584 | BB33: =SUMIFS('[1]Corn 2023'!V:V,'[1]Corn 2023'!K:K,"="&'Corn Processors'!J33,'[1]Corn 2023'!B:B,"=2023") -> 0 | BC33: Y | BD33: https://www.cardinalethanol.com/ | BE33: CSX | BF33: Yes | BK33: =IF(M33=2,10,5)+IF(Q33="ICM",10,5)+IF(X33="Y",10,5) -> 25
A34: 33 | D34: 3162 | E34: 3580 | F34: =IF(A34<300,"Active","Retired") -> Active | G34: Cargill | H34: =VLOOKUP(E34,'[1]EPA Ethanol Capacity 2024'!$B$5:$C$235,2,FALSE) -> Cargill Inc | I34: NE | J34: Blair | K34: 68008 | L34: Washington | M34: 2 | N34: 41.544697 | O34: -96.13507 | P34: 1995 | Q34: Vogelbusch | R34: =COUNTIF(G:G,"="&G34) -> 3 | AB34: Corn | AC34: D6/D5 | AD34: Website | AE34: =IF(BK34=1,"Low","High") -> High | AI34: 57902 | AJ34: =VLOOKUP(E34,'[1]Ethanol Plant Listing 2025'!$B$3:$E$220,4,FALSE) -> 210 | AK34: =+AJ34*[1]Yield!$K$4 -> 199.5 | AL34: =AK34/VLOOKUP(Q34,[1]Yield!$E$5:$F$14,2,FALSE) -> 68.793103 | AO34: =ROUND((+AL34*13.1*1000000)/2000,-3) -> 451000 | AQ34: =IF(G34="POET Biorefining",G34,IF(T34="FQPT HI Pro",T34,IF(Z34="ICM FOT",Z34,IF(Q34="ICM",Q34,IF(Q34="ADM",Q34,"None"))))) -> None | AR34: =VLOOKUP(AQ34,[1]Yield!$A$5:$B$10,2,FALSE) -> 0.815 | AS34: =(AL34)*AR34 -> 56.066379 | AT34: Likely | AX34: =IFERROR(VLOOKUP(E34,[1]Sheet3!$C$2:$E$68,2,FALSE),"None") -> None | AY34: =IFERROR(VLOOKUP(AX34,[1]Sheet3!$H$3:$I$5,2,FALSE),0) -> 0 | AZ34: =AJ34 -> 210 | BA34: =+AJ34*6.85*0.48/2 -> 345.24 | BB34: =SUMIFS('[1]Corn 2023'!V:V,'[1]Corn 2023'!K:K,"="&'Corn Processors'!J34,'[1]Corn 2023'!B:B,"=2023") -> 0 | BD34: https://www.cargill.com/home | BE34: UP | BF34: Yes | BK34: =IF(M34=2,10,5)+IF(Q34="ICM",10,5)+IF(X34="Y",10,5) -> 20
A35: 34 | D35: 3163 | E35: 3581 | F35: =IF(A35<300,"Active","Retired") -> Active | G35: Cargill | H35: =VLOOKUP(E35,'[1]EPA Ethanol Capacity 2024'!$B$5:$C$235,2,FALSE) -> Cargill Inc | I35: IA | J35: Eddyville | K35: 52553 | L35: Wapello | M35: 2 | N35: 41.55 | O35: -92.6343 | P35: 0 | Q35: Wet Mill | R35: =COUNTIF(G:G,"="&G35) -> 3 | U35: CHP | AB35: Corn | AC35: D6/D5 | AD35: Website | AE35: =IF(BK35=1,"Low","High") -> High | AF35: 70.1 | AG35: =0.165*365 -> 60.225 | AH35: 91-A-236 | AJ35: =VLOOKUP(E35,'[1]Ethanol Plant Listing 2025'!$B$3:$E$220,4,FALSE) -> 71 | AK35: =+AJ35*[1]Yield!$K$4 -> 67.45 | AL35: =AK35/VLOOKUP(Q35,[1]Yield!$E$5:$F$14,2,FALSE) -> 24.527273 | AO35: =ROUND((+AL35*13.1*1000000)/2000,-3) -> 161000 | AQ35: =IF(G35="POET Biorefining",G35,IF(T35="FQPT HI Pro",T35,IF(Z35="ICM FOT",Z35,IF(Q35="ICM",Q35,IF(Q35="ADM",Q35,"None"))))) -> None | AR35: =VLOOKUP(AQ35,[1]Yield!$A$5:$B$10,2,FALSE) -> 0.815 | AS35: =(AL35)*AR35 -> 19.989727 | AT35: Likely | AX35: =IFERROR(VLOOKUP(E35,[1]Sheet3!$C$2:$E$68,2,FALSE),"None") -> None | AY35: =IFERROR(VLOOKUP(AX35,[1]Sheet3!$H$3:$I$5,2,FALSE),0) -> 0 | AZ35: =AJ35 -> 71 | BA35: =+AJ35*6.85*0.48/2 -> 116.724 | BB35: =SUMIFS('[1]Corn 2023'!V:V,'[1]Corn 2023'!B:B,"=2023",'[1]Corn 2023'!L:L,"="&'Corn Processors'!L35) -> 58400 | BD35: https://www.cargill.com/home | BE35: UP/BNSF | BF35: Yes | BK35: =IF(M35=2,10,5)+IF(Q35="ICM",10,5)+IF(X35="Y",10,5) -> 20
A36: 35 | D36: 3164 | E36: 3582 | F36: =IF(A36<300,"Active","Retired") -> Active | G36: Cargill | H36: =VLOOKUP(E36,'[1]EPA Ethanol Capacity 2024'!$B$5:$C$235,2,FALSE) -> Cargill Inc | I36: IA | J36: Fort Dodge | K36: 50501 | L36: Webster | M36: 2 | N36: 42.506334 | O36: -94.313203 | P36: 2013 | Q36: Wet Mill | R36: =COUNTIF(G:G,"="&G36) -> 3 | AB36: Corn | AC36: D6/D5 | AD36: Website | AE36: =IF(BK36=1,"Low","High") -> High | AF36: 130 | AG36: 115 | AH36: 07-A-846 | AJ36: =VLOOKUP(E36,'[1]Ethanol Plant Listing 2025'!$B$3:$E$220,4,FALSE) -> 130 | AK36: =+AJ36*[1]Yield!$K$4 -> 123.5 | AL36: =AK36/VLOOKUP(Q36,[1]Yield!$E$5:$F$14,2,FALSE) -> 44.909091 | AO36: =ROUND((+AL36*13.1*1000000)/2000,-3) -> 294000 | AQ36: =IF(G36="POET Biorefining",G36,IF(T36="FQPT HI Pro",T36,IF(Z36="ICM FOT",Z36,IF(Q36="ICM",Q36,IF(Q36="ADM",Q36,"None"))))) -> None | AR36: =VLOOKUP(AQ36,[1]Yield!$A$5:$B$10,2,FALSE) -> 0.815 | AS36: =(AL36)*AR36 -> 36.600909 | AT36: Likely | AX36: =IFERROR(VLOOKUP(E36,[1]Sheet3!$C$2:$E$68,2,FALSE),"None") -> None | AY36: =IFERROR(VLOOKUP(AX36,[1]Sheet3!$H$3:$I$5,2,FALSE),0) -> 0 | AZ36: =AJ36 -> 130 | BA36: =+AJ36*6.85*0.48/2 -> 213.72 | BB36: =SUMIFS('[1]Corn 2023'!V:V,'[1]Corn 2023'!B:B,"=2023",'[1]Corn 2023'!L:L,"="&'Corn Processors'!L36) -> 195000 | BD36: https://www.cargill.com/home | BE36: UP/CN | BF36: Yes | BK36: =IF(M36=2,10,5)+IF(Q36="ICM",10,5)+IF(X36="Y",10,5) -> 20
A37: 36 | C37: 70150 | D37: 3166 | E37: 3585 | F37: =IF(A37<300,"Active","Retired") -> Active | G37: Chief Industries | H37: =VLOOKUP(E37,'[1]EPA Ethanol Capacity 2024'!$B$5:$C$235,2,FALSE) -> Chief Ethanol Fuels Inc | I37: NE | J37: Hastings | K37: 68901 | L37: Adams | M37: 2 | N37: 40.585 | O37: -98.318889 | P37: 1985 | Q37: Vogelbusch | R37: =COUNTIF(G:G,"="&G37) -> 2 | AB37: Corn | AC37: D6 | AD37: Website | AE37: =IF(BK37=1,"Low","High") -> High | AF37: 53 | AG37: 53 | AH37: AIR>CONSTRUCTION | AI37: 84534 | AJ37: =VLOOKUP(E37,'[1]Ethanol Plant Listing 2025'!$B$3:$E$220,4,FALSE) -> 70 | AK37: =+AJ37*[1]Yield!$K$4 -> 66.5 | AL37: =AK37/VLOOKUP(Q37,[1]Yield!$E$5:$F$14,2,FALSE) -> 22.931034 | AO37: =ROUND((+AL37*13.1*1000000)/2000,-3) -> 150000 | AQ37: =IF(G37="POET Biorefining",G37,IF(T37="FQPT HI Pro",T37,IF(Z37="ICM FOT",Z37,IF(Q37="ICM",Q37,IF(Q37="ADM",Q37,"None"))))) -> None | AR37: =VLOOKUP(AQ37,[1]Yield!$A$5:$B$10,2,FALSE) -> 0.815 | AS37: =(AL37)*AR37 -> 18.688793 | AT37: Y | AV37: =+AX37 -> Tall Grass | AX37: =IFERROR(VLOOKUP(E37,[1]Sheet3!$C$2:$E$68,2,FALSE),"None") -> Tall Grass | AY37: =IFERROR(VLOOKUP(AX37,[1]Sheet3!$H$3:$I$5,2,FALSE),0) -> 30 | AZ37: =AJ37 -> 70 | BA37: =+AJ37*6.85*0.48/2 -> 115.08 | BB37: =SUMIFS('[1]Corn 2023'!V:V,'[1]Corn 2023'!K:K,"="&'Corn Processors'!J37,'[1]Corn 2023'!B:B,"=2023") -> 0 | BD37: https://chiefethanol.com/ | BE37: UP/BNSF | BF37: Yes | BJ37: Member | BK37: =IF(M37=2,10,5)+IF(Q37="ICM",10,5)+IF(X37="Y",10,5) -> 20 | BL37: 10/31/22 Central Indiana Ethanol purchases from Louis Dreyfus for an undisclosed amount, Ocean Park was the advisor
A38: 37 | C38: 70241 | D38: 3167 | E38: 3586 | F38: =IF(A38<300,"Active","Retired") -> Active | G38: Chief Industries | H38: =VLOOKUP(E38,'[1]EPA Ethanol Capacity 2024'!$B$5:$C$235,2,FALSE) -> Chief Ethanol Fuels Inc | I38: NE | J38: Lexington | K38: 68850 | L38: Dawson | M38: 2 | N38: 40.746088 | O38: -99.767869 | P38: 2006 | Q38: Vogelbusch | R38: =COUNTIF(G:G,"="&G38) -> 2 | AB38: Corn | AC38: D6 | AD38: Website | AE38: =IF(BK38=1,"Low","High") -> High | AF38: 80 | AG38: 65 | AH38: AIR>CONSTRUCTION | AI38: 58049 | AJ38: =VLOOKUP(E38,'[1]Ethanol Plant Listing 2025'!$B$3:$E$220,4,FALSE) -> 52 | AK38: =+AJ38*[1]Yield!$K$4 -> 49.4 | AL38: =AK38/VLOOKUP(Q38,[1]Yield!$E$5:$F$14,2,FALSE) -> 17.034483 | AO38: =ROUND((+AL38*13.1*1000000)/2000,-3) -> 112000 | AQ38: =IF(G38="POET Biorefining",G38,IF(T38="FQPT HI Pro",T38,IF(Z38="ICM FOT",Z38,IF(Q38="ICM",Q38,IF(Q38="ADM",Q38,"None"))))) -> None | AR38: =VLOOKUP(AQ38,[1]Yield!$A$5:$B$10,2,FALSE) -> 0.815 | AS38: =(AL38)*AR38 -> 13.883103 | AT38: Y | AV38: =+AX38 -> Tall Grass | AX38: =IFERROR(VLOOKUP(E38,[1]Sheet3!$C$2:$E$68,2,FALSE),"None") -> Tall Grass | AY38: =IFERROR(VLOOKUP(AX38,[1]Sheet3!$H$3:$I$5,2,FALSE),0) -> 30 | AZ38: =AJ38 -> 52 | BA38: =+AJ38*6.85*0.48/2 -> 85.488 | BB38: =SUMIFS('[1]Corn 2023'!V:V,'[1]Corn 2023'!K:K,"="&'Corn Processors'!J38,'[1]Corn 2023'!B:B,"=2023") -> 0 | BD38: https://chiefethanol.com/ | BE38: UP | BF38: Yes | BJ38: Member | BK38: =IF(M38=2,10,5)+IF(Q38="ICM",10,5)+IF(X38="Y",10,5) -> 20
A39: 38 | C39: 70078 | D39: 2644 | E39: 3587 | F39: =IF(A39<300,"Active","Retired") -> Active | G39: Chippewa Valley Ethanol Co. | H39: =VLOOKUP(E39,'[1]EPA Ethanol Capacity 2024'!$B$5:$C$235,2,FALSE) -> Chippewa Valley Ethanol Co LLLP | I39: MN | J39: Benson | K39: 56215 | L39: Swift | M39: 2 | N39: 45.327 | O39: -95.6377 | P39: 1996 | Q39: Delta-T | R39: =COUNTIF(G:G,"="&G39) -> 1 | X39: White Fox ICM | Z39: Fluid Quip | AB39: Corn | AC39: D6 | AD39: Website | AE39: =IF(BK39=1,"Low","High") -> High | AI39: 77755 | AJ39: =VLOOKUP(E39,'[1]Ethanol Plant Listing 2025'!$B$3:$E$220,4,FALSE) -> 50 | AK39: =+AJ39*[1]Yield!$K$4 -> 47.5 | AL39: =AK39/VLOOKUP(Q39,[1]Yield!$E$5:$F$14,2,FALSE) -> 16.493056 | AO39: =ROUND((+AL39*13.1*1000000)/2000,-3) -> 108000 | AP39: Ring Dryer | AQ39: =IF(G39="POET Biorefining",G39,IF(T39="FQPT HI Pro",T39,IF(Z39="ICM FOT",Z39,IF(Q39="ICM",Q39,IF(Q39="ADM",Q39,"None"))))) -> None | AR39: =VLOOKUP(AQ39,[1]Yield!$A$5:$B$10,2,FALSE) -> 0.815 | AS39: =(AL39)*AR39 -> 13.44184 | AT39: Likely | AX39: =IFERROR(VLOOKUP(E39,[1]Sheet3!$C$2:$E$68,2,FALSE),"None") -> None | AY39: =IFERROR(VLOOKUP(AX39,[1]Sheet3!$H$3:$I$5,2,FALSE),0) -> 0 | AZ39: =AJ39 -> 50 | BA39: =+AJ39*6.85*0.48/2 -> 82.2 | BB39: =SUMIFS('[1]Corn 2023'!V:V,'[1]Corn 2023'!K:K,"="&'Corn Processors'!J39,'[1]Corn 2023'!B:B,"=2023") -> 0 | BD39: http://cvec.com/ | BE39: BNSF | BF39: No | BJ39: Member | BK39: =IF(M39=2,10,5)+IF(Q39="ICM",10,5)+IF(X39="Y",10,5) -> 20 | BL39: 5/27/16 Chief purchases from Cornhusker
A40: 39 | D40: 2436 | E40: 3588 | F40: =IF(A40<300,"Active","Retired") -> Active | G40: CHS | H40: =VLOOKUP(E40,'[1]EPA Ethanol Capacity 2024'!$B$5:$C$235,2,FALSE) -> CHS - Annawan | I40: IL | J40: Annawan | K40: 61234 | L40: Henry | M40: 2 | N40: 41.393398 | O40: -89.872214 | P40: 2008 | Q40: ICM | R40: =COUNTIF(G:G,"="&G40) -> 2 | S40: EP3 | X40: White Fox | AB40: Corn | AC40: D6 | AD40: https://www.chs-illinois.com/grain/cash-bids/ | AE40: =IF(BK40=1,"Low","High") -> High | AJ40: =VLOOKUP(E40,'[1]Ethanol Plant Listing 2025'!$B$3:$E$220,4,FALSE) -> 130 | AK40: =+AJ40*[1]Yield!$K$4 -> 123.5 | AL40: =AK40/VLOOKUP(Q40,[1]Yield!$E$5:$F$14,2,FALSE) -> 41.864407 | AO40: =ROUND((+AL40*13.1*1000000)/2000,-3) -> 274000 | AP40: Rotary Dryer | AQ40: =IF(G40="POET Biorefining",G40,IF(T40="FQPT HI Pro",T40,IF(Z40="ICM FOT",Z40,IF(Q40="ICM",Q40,IF(Q40="ADM",Q40,"None"))))) -> ICM | AR40: =VLOOKUP(AQ40,[1]Yield!$A$5:$B$10,2,FALSE) -> 0.9 | AS40: =(AL40)*AR40 -> 37.677966 | AT40: Likely | AX40: =IFERROR(VLOOKUP(E40,[1]Sheet3!$C$2:$E$68,2,FALSE),"None") -> None | AY40: =IFERROR(VLOOKUP(AX40,[1]Sheet3!$H$3:$I$5,2,FALSE),0) -> 0 | AZ40: =AJ40 -> 130 | BA40: =+AJ40*6.85*0.48/2 -> 213.72 | BB40: =SUMIFS('[1]Corn 2023'!V:V,'[1]Corn 2023'!K:K,"="&'Corn Processors'!J40,'[1]Corn 2023'!B:B,"=2023") -> 0 | BD40: https://www.chsinc.com/our-businesses/renewable-fuels | BE40: IAIS | BF40: Yes | BJ40: Member | BK40: =IF(M40=2,10,5)+IF(Q40="ICM",10,5)+IF(X40="Y",10,5) -> 25
...

Sheet Summary
A1: fiber_technology | B1: count_rows | C1: count_plants | D1: min_ci | E1: max_ci | F1: avg_ci | G1: median_ci | H1: std_ci
A2: EDENIQ | B2: 35 | C2: 35 | D2: 21.93 | E2: 40.14 | F2: 27.122571 | G2: 26.38 | H2: 4.1116623
A3: BPX | B3: 28 | C3: 28 | D3: 23.48 | E3: 30.39 | F3: 26.903571 | G3: 26.955 | H3: 1.6786441
A4: SOLITON | B4: 13 | C4: 13 | D4: 23 | E4: 30.3 | F4: 25.860769 | G4: 25.28 | H4: 1.7794543
A5: Proprietary Process | B5: 4 | C5: 4 | D5: 25.94 | E5: 31.05 | F5: 27.975 | G5: 27.455 | H5: 2.2803289
A6: POET | B6: 2 | C6: 2 | D6: 25.25 | E6: 30.1 | F6: 27.675 | G6: 27.675 | H6: 3.4294679

Sheet Fiber Rows
A1: facility_id | B1: plant_name | C1: ownership | D1: state | E1: city | F1: feedstock | G1: pathway_type | H1: fiber_technology_raw | I1: fiber_technology | J1: ci_score | K1: coproduct_type | L1: gas_supply | M1: electricity_type | N1: detail_date | O1: program
A2: 70144 | B2: Absolute Energy | C2: Absolute Energy | D2: IA | E2: St. Ansgar | F2: Corn Fiber (012) | G2: Fiber | H2: EDENIQ | I2: EDENIQ | J2: 29.68 | L2: Natural Gas | M2: Grid Electricity | N2: 2026-02-11 | O2: CA
A3: 70087 | B3: Al-Corn Clean Fuel | C3: Al–Corn Clean Fuel | D3: MN | E3: Claremont | F3: Corn Fiber (012) | G3: Fiber | H3: EDENIQ | I3: EDENIQ | J3: 26.86 | L3: Natural Gas | M3: Grid Electricity | N3: 2026-02-11 | O3: CA
A4: 70247 | B4: Arkalon Ethanol LLC | C4: Conestoga Energy | D4: KS | E4: Liberal | F4: Corn Fiber (012) | G4: Fiber | H4: EDENIQ | I4: EDENIQ | J4: 24.39 | L4: Natural Gas | M4: Grid Electricity | N4: 2026-02-11 | O4: CA
A5: 70130 | B5: Badger State Ethanol LLC | C5: Badger State Ethanol | D5: WI | E5: Monroe | F5: Corn Fiber (012) | G5: Fiber | H5: EDENIQ | I5: EDENIQ | J5: 27.22 | L5: Natural Gas | M5: Grid Electricity | N5: 2026-02-11 | O5: CA
A6: 70117 | B6: Bonanza Bioenergy LLC | C6: Conestoga Energy | D6: KS | E6: Garden City | F6: Corn Fiber (012) | G6: Fiber | H6: EDENIQ | I6: EDENIQ | J6: 24.44 | L6: Natural Gas | M6: Grid Electricity | N6: 2026-02-11 | O6: CA
A7: 70150 | B7: Chief Ethanol Fuels Inc | C7: Chief Industries | D7: NE | E7: Hastings | F7: Corn Fiber (012) | G7: Fiber | H7: EDENIQ | I7: EDENIQ | J7: 40.14 | L7: Natural Gas | M7: Grid Electricity | N7: 2026-02-11 | O7: CA
A8: 70241 | B8: Chief Ethanol Fuels Inc | C8: Chief Industries | D8: NE | E8: Lexington | F8: Corn Fiber (012) | G8: Fiber | H8: EDENIQ | I8: EDENIQ | J8: 36.17 | L8: Natural Gas | M8: Grid Electricity | N8: 2026-02-11 | O8: CA
A9: 70078 | B9: Chippewa Valley Ethanol Co LLLP | C9: Chippewa Valley Ethanol Co. | D9: MN | E9: Benson | F9: Corn Fiber (012) | G9: Fiber | H9: EDENIQ | I9: EDENIQ | J9: 29 | L9: Natural Gas | M9: Grid Electricity | N9: 2026-02-11 | O9: CA
A10: 70082 | B10: Denco II LLC | C10: DENCO II | D10: MN | E10: Morris | F10: Corn Fiber (012) | G10: Fiber | H10: SOLITON | I10: SOLITON | J10: 30.3 | L10: Natural Gas | M10: Grid Electricity | N10: 2026-02-11 | O10: CA
A11: 70093 | B11: E Energy Adams LLC | C11: E Energy Adams, LLC | D11: NE | E11: Adams | F11: Corn Fiber (012) | G11: Fiber | H11: EDENIQ | I11: EDENIQ | J11: 30.47 | L11: Natural Gas | M11: Grid Electricity | N11: 2026-02-11 | O11: CA
A12: 71287 | B12: Elite Octane LLC | C12: Elite Octane | D12: IA | E12: Atlantic | F12: Corn Fiber (012) | G12: Fiber | H12: EDENIQ | I12: EDENIQ | J12: 28.35 | L12: Natural Gas | M12: Grid Electricity | N12: 2026-02-11 | O12: CA
A13: 70722 | B13: Huron Energy LLC | C13: Glacial Lakes Cooperative | D13: SD | E13: Huron | F13: Corn Fiber (012) | G13: Fiber | H13: EDENIQ | I13: EDENIQ | J13: 29.31 | L13: Natural Gas | M13: Grid Electricity | N13: 2026-02-11 | O13: CA
